Workbook
Name __123Graph_A: #REF!
Name __123Graph_A: #REF!
Name __123Graph_A: #REF!
Name __123Graph_B: #REF!
Name __123Graph_B: #REF!
Name __123Graph_B: #REF!
Name __123Graph_C: #REF!
Name __123Graph_C: #REF!
Name __123Graph_C: #REF!
Name __123Graph_D: #REF!
Name __123Graph_D: #REF!
Name __123Graph_D: #REF!
Name __123Graph_E: #REF!
Name __123Graph_E: #REF!
Name __123Graph_E: #REF!
Name __123Graph_F: #REF!
Name __123Graph_F: #REF!
Name __123Graph_F: #REF!
Name __123Graph_X: #REF!
Name __123Graph_X: #REF!
Name __123Graph_X: #REF!
Name _1: #REF!
Name _1: #REF!
Name _10: #REF!
Name _10: #REF!
Name _10: #REF!
Name _11: #REF!
Name _11: #REF!
Name _11: #REF!
Name _12: #REF!
Name _12: #REF!
Name _12: #REF!
Name _13: #REF!
Name _13: #REF!
Name _14: #REF!
Name _14: #REF!
Name _15: #REF!
Name _15: #REF!
Name _15: #REF!
Name _16: #REF!
Name _16: #REF!
Name _16: #REF!
Name _17: #REF!
Name _17: #REF!
Name _17: #REF!
Name _18: #REF!
Name _18: #REF!
Name _18: #REF!
Name _19: #REF!
Name _19: #REF!
Name _19: #REF!
Name _1A: #REF!
Name _1A: #REF!
Name _2: #REF!
Name _2: #REF!
Name _20: #REF!
Name _20: #REF!
Name _21: #REF!
Name _21: #REF!
Name _22: #REF!

Sheet Financials
B1: Income Statement | C1: Period 1 | D1: Period 2 | E1: Period 3 | F1: Period 4 | G1: Period 5 | H1: Period 6 | I1: Period 7 | J1: Period 8 | K1: Period 9 | L1: Period 10 | M1: Period 11 | N1: Period 12 | O1: Period 13 | P1: Period 14 | Q1: Period 15 | R1: Period 16 | S1: Period 17 | T1: Period 18 | U1: Period 19 | V1: Period 20 | W1: Period 21 | X1: Period 22 | Y1: Period 23 | Z1: Period 24 | AA1: Period 25 | AB1: Period 26 | AC1: Period 27 | AD1: Period 28 | AE1: Period 29 | AF1: Period 30 | AG1: Period 31 | AH1: Period 32 | AI1: Period 33 | AJ1: Period 34 | AK1: Period 35 | AL1: Period 36 | AM1: Period 37 | AN1: Period 38 | AO1: Period 39 | AP1: Period 40
C2: Values | D2: Values | E2: Values | F2: Values | G2: Values | H2: Values | I2: Values | J2: Values | K2: Values | L2: Values | M2: Values | N2: Values | O2: Values | P2: Values | Q2: Values | R2: Values | S2: Values | T2: Values | U2: Values | V2: Values | W2: Values | X2: Values | Y2: Values | Z2: Values | AA2: Values | AB2: Values | AC2: Values | AD2: Values | AE2: Values | AF2: Values | AG2: Values | AH2: Values | AI2: Values | AJ2: Values | AK2: Values | AL2: Values | AM2: Values | AN2: Values | AO2: Values | AP2: Values | AR2: 0 | AT2: 0 | AV2: 0 | AX2: 0 | AZ2: 0 | BB2: 0 | BD2: 0 | BF2: 0 | BH2: 0 | BJ2: 0 | BL2: 0 | BN2: 0 | BP2: 0 | BR2: 0 | BT2: 0 | BV2: 0 | BX2: 0 | BZ2: 0 | CB2: 0 | CD2: 0 | CF2: 0 | CH2: 0 | CJ2: 0 | CL2: 0 | CN2: 0 | CP2: 0 | CR2: 0 | CT2: 0 | CV2: 0 | CX2: 0 | CZ2: 0 | DB2: 0 | DD2: 0 | DF2: 0 | DH2: 0 | DJ2: 0 | DL2: 0 | DN2: 0 | DP2: 0 | DR2: 0 | DT2: 0 | DV2: 0 | DX2: 0 | DZ2: 0 | EB2: 0
A3: 0 | B3: =+#REF! -> #REF! | C3: 15339.238 | D3: 217503.04 | E3: 19056.423 | F3: 407728.31 | G3: 856519.08 | H3: 909823.4 | I3: 961018.41 | J3: 1008313.4 | K3: 1057973 | L3: 1057973 | M3: 1057973 | N3: 1057973 | O3: 1057973 | P3: 0 | Q3: 0 | AP3: 0 | AR3: 0 | AT3: 0 | AV3: 0 | AX3: 0 | AZ3: 0 | BB3: 0 | BD3: 0 | BF3: 0 | BH3: 0 | BJ3: 0 | BL3: 0 | BN3: 0 | BP3: 0 | BR3: 0 | BT3: 0 | BV3: 0 | BX3: 0 | BZ3: 0 | CB3: 0 | CD3: 0 | CF3: 0 | CH3: 0 | CJ3: 0 | CL3: 0 | CN3: 0 | CP3: 0 | CR3: 0 | CT3: 0 | CV3: 0 | CX3: 0 | CZ3: 0 | DB3: 0 | DD3: 0 | DF3: 0 | DH3: 0 | DJ3: 0 | DL3: 0 | DN3: 0 | DP3: 0 | DR3: 0 | DT3: 0 | DV3: 0 | DX3: 0 | DZ3: 0 | EB3: 0 | ED3: 0
B4: =+#REF! -> #REF! | C4: =IF(ISNUMBER(Historical!E105),Historical!E105, ) -> 100000 | D4: =IF(ISNUMBER(Historical!G105),Historical!G105, ) -> 110000 | E4: =IF(ISNUMBER(Historical!I105),Historical!I105, ) -> 120000 | F4: =IF(ISNUMBER(Projection!$H$7),IF(MONTH(Projection!H7)<>12,IF(ISNUMBER(Projection!L74),Projection!L74, ),IF(ISNUMBER(Historical!K105),Historical!K105, )), ) -> 132000 | G4: =IF(ISNUMBER(Projection!$H$7),IF(MONTH(Projection!$H$7)<>12,IF(ISNUMBER(Projection!N74),Projection!N74, ),IF(ISNUMBER(Projection!L74),Projection!L74, )), ) -> 157300 | H4: =IF(ISNUMBER(Projection!$H$7),IF(MONTH(Projection!$H$7)<>12,IF(ISNUMBER(Projection!P74),Projection!P74, ),IF(ISNUMBER(Projection!N74),Projection!N74, )), ) -> 173030 | I4: =IF(ISNUMBER(Projection!$H$7),IF(MONTH(Projection!$H$7)<>12,IF(ISNUMBER(Projection!R74),Projection!R74, ),IF(ISNUMBER(Projection!P74),Projection!P74, )), ) -> 190333 | J4: =IF(ISNUMBER(Projection!$H$7),IF(MONTH(Projection!$H$7)<>12,IF(ISNUMBER(Projection!T74),Projection!T74, ),IF(ISNUMBER(Projection!R74),Projection!R74, )), ) -> 209366.3 | K4: =IF(ISNUMBER(Projection!$H$7),IF(MONTH(Projection!$H$7)<>12,IF(ISNUMBER(Projection!Z74),Projection!Z74, ),IF(ISNUMBER(Projection!T74),Projection!T74, )), ) -> 209366.3 | L4: =IF(ISNUMBER(Projection!$H$7),IF(MONTH(Projection!$H$7)<>12,IF(ISNUMBER(Projection!AB74),Projection!AB74, ),IF(ISNUMBER(Projection!Z74),Projection!Z74, )), ) -> 209366.3 | M4: =IF(ISNUMBER(Projection!$H$7),IF(MONTH(Projection!$H$7)<>12,IF(ISNUMBER(Projection!AD74),Projection!AD74, ),IF(ISNUMBER(Projection!AB74),Projection!AB74, )), ) -> 209366.3 | N4: =IF(ISNUMBER(Projection!$H$7),IF(MONTH(Projection!$H$7)<>12,IF(ISNUMBER(Projection!AF74),Projection!AF74, ),IF(ISNUMBER(Projection!AD74),Projection!AD74, )), ) -> 209366.3 | O4: =IF(ISNUMBER(Projection!$H$7),IF(MONTH(Projection!$H$7)<>12,IF(ISNUMBER(Projection!AH74),Projection!AH74, ),IF(ISNUMBER(Projection!AF74),Projection!AF74, )), ) -> 209366.3 | R4: 0 | S4: 0 | T4: 0 | U4: 0 | V4: 0 | W4: 0 | X4: 0 | Y4: 0 | Z4: 0 | AA4: 0 | AB4: 0 | AC4: 0 | AD4: 0 | AE4: 0 | AF4: 0 | AG4: 0 | AH4: 0 | AI4: 0 | AJ4: 0 | AK4: 0 | AL4: 0 | AM4: 0 | AN4: 0 | AO4: 0 | AP4: 0 | AR4: 0 | AT4: 0 | AV4: 0 | AX4: 0 | AZ4: 0 | BB4: 0 | BD4: 0 | BF4: 0 | BH4: 0 | BJ4: 0 | BL4: 0 | BN4: 0 | BP4: 0 | BR4: 0 | BT4: 0 | BV4: 0 | BX4: 0 | BZ4: 0 | CB4: 0 | CD4: 0 | CF4: 0 | CH4: 0 | CJ4: 0 | CL4: 0 | CN4: 0 | CP4: 0 | CR4: 0 | CT4: 0 | CV4: 0 | CX4: 0 | CZ4: 0 | DB4: 0 | DD4: 0 | DF4: 0 | DH4: 0 | DJ4: 0 | DL4: 0 | DN4: 0 | DP4: 0 | DR4: 0 | DT4: 0 | DV4: 0 | DX4: 0 | DZ4: 0 | EB4: 0 | ED4: 0
B5: =+#REF! -> #REF!
B6: =+#REF! -> #REF!
B7: =+#REF! -> #REF!
B8: =+#REF! -> #REF!
B9: =+#REF! -> #REF!
B10: =+#REF! -> #REF!
B11: =+#REF! -> #REF!
B12: =+#REF! -> #REF!
B13: =+#REF! -> #REF!
B14: =+#REF! -> #REF!
B15: =+#REF! -> #REF!
B16: =+#REF! -> #REF!
... B18: =+#REF! -> #REF!
B19: =+#REF! -> #REF! | C19: 5524.5094 | D19: 207297.76 | E19: 4434.7247 | F19: 366041.15 | G19: 775480.23 | H19: 823925.26 | I19: 870663.86 | J19: 914153.37 | K19: 959817.35 | L19: 0 | M19: 0 | N19: 0 | O19: 0 | P19: 0
B20: =+#REF! -> #REF! | C20: =IF(ISNUMBER(Historical!E106),Historical!E106, ) -> 80000 | D20: =IF(ISNUMBER(Historical!G106),Historical!G106, ) -> 81000 | E20: =IF(ISNUMBER(Historical!I106),Historical!I106, ) -> 82000 | F20: =IF(ISNUMBER(Projection!H7),IF(MONTH(Projection!H7)<>12,IF(ISNUMBER(Projection!L75),Projection!L75, ),IF(ISNUMBER(Historical!K106),Historical!K106, )), ) -> 95040 | G20: =IF(ISNUMBER(Projection!H7),IF(MONTH(Projection!$H$7)<>12,IF(ISNUMBER(Projection!N75),Projection!N75, ),IF(ISNUMBER(Projection!L75),Projection!L75, )), ) -> 113256 | H20: =IF(ISNUMBER(Projection!H7),IF(MONTH(Projection!$H$7)<>12,IF(ISNUMBER(Projection!P75),Projection!P75, ),IF(ISNUMBER(Projection!N75),Projection!N75, )), ) -> 124581.6 | I20: =IF(ISNUMBER(Projection!$H$7),IF(MONTH(Projection!$H$7)<>12,IF(ISNUMBER(Projection!R75),Projection!R75, ),IF(ISNUMBER(Projection!P75),Projection!P75, )), ) -> 137039.76 | J20: =IF(ISNUMBER(Projection!H7),IF(MONTH(Projection!$H$7)<>12,IF(ISNUMBER(Projection!T75),Projection!T75, ),IF(ISNUMBER(Projection!R75),Projection!R75, )), ) -> 150743.74 | K20: =IF(ISNUMBER(Projection!H7),IF(MONTH(Projection!$H$7)<>12,IF(ISNUMBER(Projection!Z75),Projection!Z75, ),IF(ISNUMBER(Projection!T75),Projection!T75, )), ) -> 189937.11 | L20: =IF(ISNUMBER(Projection!$H$7),IF(MONTH(Projection!$H$7)<>12,IF(ISNUMBER(Projection!AB75),Projection!AB75, ),IF(ISNUMBER(Projection!Z75),Projection!Z75, )), ) -> 189937.11 | M20: =IF(ISNUMBER(Projection!$H$7),IF(MONTH(Projection!$H$7)<>12,IF(ISNUMBER(Projection!AD75),Projection!AD75, ),IF(ISNUMBER(Projection!AB75),Projection!AB75, )), ) -> 189937.11 | N20: =IF(ISNUMBER(Projection!$H$7),IF(MONTH(Projection!$H$7)<>12,IF(ISNUMBER(Projection!AF75),Projection!AF75, ),IF(ISNUMBER(Projection!AD75),Projection!AD75, )), ) -> 189937.11 | O20: =IF(ISNUMBER(Projection!$H$7),IF(MONTH(Projection!$H$7)<>12,IF(ISNUMBER(Projection!AH75),Projection!AH75, ),IF(ISNUMBER(Projection!AF75),Projection!AF75, )), ) -> 189937.11 | P20: 0 | Q20: 0 | R20: 0 | S20: 0 | T20: 0 | U20: 0 | V20: 0 | W20: 0 | X20: 0 | Y20: 0 | Z20: 0 | AA20: 0 | AB20: 0 | AC20: 0 | AD20: 0 | AE20: 0 | AF20: 0 | AG20: 0 | AH20: 0 | AI20: 0 | AJ20: 0 | AK20: 0 | AL20: 0 | AM20: 0 | AN20: 0 | AO20: 0 | AP20: 0
B21: =+#REF! -> #REF! | C21: =IF(ISNUMBER(Historical!E110),Historical!E110, )*Projection!$I$129 -> 0 | D21: =IF(ISNUMBER(Historical!G110),Historical!G110, )*Projection!$I$129 -> 0 | E21: =IF(ISNUMBER(Historical!I110),Historical!I110, )*Projection!$I$129 -> 0 | F21: =IF(ISNUMBER(Projection!H7),IF(MONTH(Projection!H7)<>12,IF(ISNUMBER(Projection!L79),Projection!L79, ),IF(ISNUMBER(Historical!K110),Historical!K110, )), )*Projection!$I$129 -> 0 | G21: =IF(ISNUMBER(Projection!$H$7),IF(MONTH(Projection!$H$7)<>12,IF(ISNUMBER(Projection!N137),Projection!N137, ),IF(ISNUMBER(Projection!L137),Projection!L137, )), ) -> 0 | H21: =IF(ISNUMBER(Projection!$H$7),IF(MONTH(Projection!$H$7)<>12,IF(ISNUMBER(Projection!P137),Projection!P137, ),IF(ISNUMBER(Projection!N137),Projection!N137, )), ) -> 0 | I21: =IF(ISNUMBER(Projection!$H$7),IF(MONTH(Projection!$H$7)<>12,IF(ISNUMBER(Projection!R137),Projection!R137, ),IF(ISNUMBER(Projection!P137),Projection!P137, )), ) -> 0 | J21: =IF(ISNUMBER(Projection!$H$7),IF(MONTH(Projection!$H$7)<>12,IF(ISNUMBER(Projection!T137),Projection!T137, ),IF(ISNUMBER(Projection!R137),Projection!R137, )), ) -> 0 | K21: =IF(ISNUMBER(Projection!$H$7),IF(MONTH(Projection!$H$7)<>12,IF(ISNUMBER(Projection!Z137),Projection!Z137, ),IF(ISNUMBER(Projection!T137),Projection!T137, )), ) -> 0 | L21: =IF(ISNUMBER(Projection!$H$7),IF(MONTH(Projection!$H$7)<>12,IF(ISNUMBER(Projection!AB137),Projection!AB137, ),IF(ISNUMBER(Projection!Z137),Projection!Z137, )), ) -> 0 | M21: =IF(ISNUMBER(Projection!$H$7),IF(MONTH(Projection!$H$7)<>12,IF(ISNUMBER(Projection!AD137),Projection!AD137, ),IF(ISNUMBER(Projection!AB137),Projection!AB137, )), ) -> 0 | N21: =IF(ISNUMBER(Projection!$H$7),IF(MONTH(Projection!$H$7)<>12,IF(ISNUMBER(Projection!AF137),Projection!AF137, ),IF(ISNUMBER(Projection!AD137),Projection!AD137, )), ) -> 0 | O21: =IF(ISNUMBER(Projection!$H$7),IF(MONTH(Projection!$H$7)<>12,IF(ISNUMBER(Projection!AH137),Projection!AH137, ),IF(ISNUMBER(Projection!AF137),Projection!AF137, )), ) -> 0
B22: =+#REF! -> #REF!
B23: =+#REF! -> #REF!
B24: =+#REF! -> #REF!
B25: =+#REF! -> #REF!
A26: 0 | B26: =+#REF! -> #REF!
B27: =+#REF! -> #REF!
B28: =+#REF! -> #REF!
B29: =+#REF! -> #REF!
B30: =+#REF! -> #REF!
B31: =+#REF! -> #REF!
B32: =+#REF! -> #REF!
A33: 0 | B33: =+#REF! -> #REF!
B34: =+#REF! -> #REF!
B35: =+#REF! -> #REF! | C35: =C3-C19 -> 9814.7286 | D35: =D3-D19 -> 10205.272 | E35: =E3-E19 -> 14621.699 | F35: =F3-F19 -> 41687.164 | G35: =G3-G19 -> 81038.855 | H35: =H3-H19 -> 85898.138 | I35: =I3-I19 -> 90354.549 | J35: =J3-J19 -> 94159.984 | ... AP35: =AP3-AP19 -> 0
B36: =+#REF! -> #REF! | C36: 59742.618 | D36: 6119.191 | E36: 5670.4059 | F36: 8134.2513 | G36: 14892.779 | H36: 16150.423 | I36: 17427.497 | J36: 18691.182 | K36: 20042.504 | L36: 1994.1003 | M36: 1994.1003 | N36: 1994.1003 | O36: 1994.1003
A37: 0 | B37: =+#REF! -> #REF! | C37: =IF(ISNUMBER(Historical!E108),Historical!E108, ) -> 5000 | D37: =IF(ISNUMBER(Historical!G108),Historical!G108, ) -> 5100 | E37: =IF(ISNUMBER(Historical!I108),Historical!I108, ) -> 5200 | F37: =IF(ISNUMBER(Projection!H7),IF(MONTH(Projection!H7)<>12,IF(ISNUMBER(Projection!L77),Projection!L77, ),IF(ISNUMBER(Historical!K108),Historical!K108, )), ) -> 6600 | G37: =IF(ISNUMBER(Projection!H7),IF(MONTH(Projection!$H$7)<>12,IF(ISNUMBER(Projection!N77),Projection!N77, ),IF(ISNUMBER(Projection!L77),Projection!L77, )), ) -> 7865 | H37: =IF(ISNUMBER(Projection!H7),IF(MONTH(Projection!$H$7)<>12,IF(ISNUMBER(Projection!P77),Projection!P77, ),IF(ISNUMBER(Projection!N77),Projection!N77, )), ) -> 8651.5 | I37: =IF(ISNUMBER(Projection!H7),IF(MONTH(Projection!$H$7)<>12,IF(ISNUMBER(Projection!R77),Projection!R77, ),IF(ISNUMBER(Projection!P77),Projection!P77, )), ) -> 9516.65 | J37: =IF(ISNUMBER(Projection!H7),IF(MONTH(Projection!$H$7)<>12,IF(ISNUMBER(Projection!T77),Projection!T77, ),IF(ISNUMBER(Projection!R77),Projection!R77, )), ) -> 10468.315 | K37: =IF(ISNUMBER(Projection!H7),IF(MONTH(Projection!$H$7)<>12,IF(ISNUMBER(Projection!Z77),Projection!Z77, ),IF(ISNUMBER(Projection!T77),Projection!T77, )), ) -> 3650.9408 | L37: =IF(ISNUMBER(Projection!H7),IF(MONTH(Projection!$H$7)<>12,IF(ISNUMBER(Projection!AB77),Projection!AB77, ),IF(ISNUMBER(Projection!Z77),Projection!Z77, )), ) -> 3650.9408 | M37: =IF(ISNUMBER(Projection!$H$7),IF(MONTH(Projection!$H$7)<>12,IF(ISNUMBER(Projection!AD77),Projection!AD77, ),IF(ISNUMBER(Projection!AB77),Projection!AB77, )), ) -> 3650.9408 | N37: =IF(ISNUMBER(Projection!$H$7),IF(MONTH(Projection!$H$7)<>12,IF(ISNUMBER(Projection!AF77),Projection!AF77, ),IF(ISNUMBER(Projection!AD77),Projection!AD77, )), ) -> 3650.9408 | O37: =IF(ISNUMBER(Projection!$H$7),IF(MONTH(Projection!$H$7)<>12,IF(ISNUMBER(Projection!AH77),Projection!AH77, ),IF(ISNUMBER(Projection!AF77),Projection!AF77, )), ) -> 3650.9408 | P37: 0 | Q37: 0 | R37: 0 | S37: 0 | T37: 0 | U37: 0 | V37: 0 | W37: 0 | X37: 0 | Y37: 0 | Z37: 0 | AA37: 0 | AB37: 0 | AC37: 0 | AD37: 0 | AE37: 0 | AF37: 0 | AG37: 0 | AH37: 0 | AI37: 0 | AJ37: 0 | AK37: 0 | AL37: 0 | AM37: 0 | AN37: 0 | AO37: 0 | AP37: 0
B38: =+#REF! -> #REF! | C38: =IF(ISNUMBER(Historical!E111),Historical!E111, ) -> 100 | D38: =IF(ISNUMBER(Historical!G111),Historical!G111, ) -> 110 | E38: =IF(ISNUMBER(Historical!I111),Historical!I111, ) -> 120 | F38: =IF(ISNUMBER(Projection!H7),IF(MONTH(Projection!H7)<>12,IF(ISNUMBER(Projection!L80),Projection!L80, ),IF(ISNUMBER(Historical!K111),Historical!K111, )), ) -> 260 | G38: =IF(ISNUMBER(Projection!H7),IF(MONTH(Projection!$H$7)<>12,IF(ISNUMBER(Projection!N80),Projection!N80, ),IF(ISNUMBER(Projection!L80),Projection!L80, )), ) -> 260 | H38: =IF(ISNUMBER(Projection!H7),IF(MONTH(Projection!$H$7)<>12,IF(ISNUMBER(Projection!P80),Projection!P80, ),IF(ISNUMBER(Projection!N80),Projection!N80, )), ) -> 260 | I38: =IF(ISNUMBER(Projection!H7),IF(MONTH(Projection!$H$7)<>12,IF(ISNUMBER(Projection!R80),Projection!R80, ),IF(ISNUMBER(Projection!P80),Projection!P80, )), ) -> 260 | J38: =IF(ISNUMBER(Projection!H7),IF(MONTH(Projection!$H$7)<>12,IF(ISNUMBER(Projection!T80),Projection!T80, ),IF(ISNUMBER(Projection!R80),Projection!R80, )), ) -> 260 | K38: =IF(ISNUMBER(Projection!H7),IF(MONTH(Projection!$H$7)<>12,IF(ISNUMBER(Projection!Z80),Projection!Z80, ),IF(ISNUMBER(Projection!T80),Projection!T80, )), ) -> 260 | L38: =IF(ISNUMBER(Projection!H7),IF(MONTH(Projection!$H$7)<>12,IF(ISNUMBER(Projection!AB80),Projection!AB80, ),IF(ISNUMBER(Projection!Z80),Projection!Z80, )), ) -> 260 | M38: =IF(ISNUMBER(Projection!$H$7),IF(MONTH(Projection!$H$7)<>12,IF(ISNUMBER(Projection!AD80),Projection!AD80, ),IF(ISNUMBER(Projection!AB80),Projection!AB80, )), ) -> 260 | N38: =IF(ISNUMBER(Projection!$H$7),IF(MONTH(Projection!$H$7)<>12,IF(ISNUMBER(Projection!AF80),Projection!AF80, ),IF(ISNUMBER(Projection!AD80),Projection!AD80, )), ) -> 260 | O38: =IF(ISNUMBER(Projection!$H$7),IF(MONTH(Projection!$H$7)<>12,IF(ISNUMBER(Projection!AH80),Projection!AH80, ),IF(ISNUMBER(Projection!AF80),Projection!AF80, )), ) -> 260
B39: =+#REF! -> #REF! | C39: =IF(ISNUMBER(Historical!E110),Historical!E110, )*Projection!$I$131 -> 2000 | D39: =IF(ISNUMBER(Historical!G110),Historical!G110, )*Projection!$I$131 -> 2100 | E39: =IF(ISNUMBER(Historical!I110),Historical!I110, )*Projection!$I$131 -> 2200 | F39: =IF(ISNUMBER(Projection!H7),IF(MONTH(Projection!H7)<>12,IF(ISNUMBER(Projection!L79),Projection!L79, ),IF(ISNUMBER(Historical!K110),Historical!K110, )), )*Projection!$I$131 -> 4602 | G39: =IF(ISNUMBER(Projection!$H$7),IF(MONTH(Projection!$H$7)<>12,IF(ISNUMBER(Projection!N139),Projection!N139, ),IF(ISNUMBER(Projection!L139),Projection!L139, )), ) -> 6902 | H39: =IF(ISNUMBER(Projection!$H$7),IF(MONTH(Projection!$H$7)<>12,IF(ISNUMBER(Projection!P139),Projection!P139, ),IF(ISNUMBER(Projection!N139),Projection!N139, )), ) -> 6902 | I39: =IF(ISNUMBER(Projection!$H$7),IF(MONTH(Projection!$H$7)<>12,IF(ISNUMBER(Projection!R139),Projection!R139, ),IF(ISNUMBER(Projection!P139),Projection!P139, )), ) -> 6902 | J39: =IF(ISNUMBER(Projection!$H$7),IF(MONTH(Projection!$H$7)<>12,IF(ISNUMBER(Projection!T139),Projection!T139, ),IF(ISNUMBER(Projection!R139),Projection!R139, )), ) -> 6902 | K39: =IF(ISNUMBER(Projection!$H$7),IF(MONTH(Projection!$H$7)<>12,IF(ISNUMBER(Projection!Z139),Projection!Z139, ),IF(ISNUMBER(Projection!T139),Projection!T139, )), ) -> 4602 | L39: =IF(ISNUMBER(Projection!$H$7),IF(MONTH(Projection!$H$7)<>12,IF(ISNUMBER(Projection!AB139),Projection!AB139, ),IF(ISNUMBER(Projection!Z139),Projection!Z139, )), ) -> 4602 | M39: =IF(ISNUMBER(Projection!$H$7),IF(MONTH(Projection!$H$7)<>12,IF(ISNUMBER(Projection!AD139),Projection!AD139, ),IF(ISNUMBER(Projection!AB139),Projection!AB139, )), ) -> 4602 | N39: =IF(ISNUMBER(Projection!$H$7),IF(MONTH(Projection!$H$7)<>12,IF(ISNUMBER(Projection!AF139),Projection!AF139, ),IF(ISNUMBER(Projection!AD139),Projection!AD139, )), ) -> 4602 | O39: =IF(ISNUMBER(Projection!$H$7),IF(MONTH(Projection!$H$7)<>12,IF(ISNUMBER(Projection!AH139),Projection!AH139, ),IF(ISNUMBER(Projection!AF139),Projection!AF139, )), ) -> 4602
B40: =+#REF! -> #REF!
B41: =+#REF! -> #REF!
...

Sheet Historical
B2: Debtor / Group Name: | E2: Date : | H2: Proposed Unit :
B3: Generic Niaga / Generic Group | E3: 45598 | H3: Divisi Corporate Banking 2
B5: Status of Financial Statement
B6: Period of Financial Statement | E6: Status | G6: Public Accountant Firm | I6: Classification | K6: Opini | O6: --- | P6: --- | Q6: --- | BG6: Status-Opini | BI6: Kantor akuntan
B7: =+E13 -> 44561 | E7: Audited | G7: KAP | K7: Unqualified | O7: Audited | P7: A | Q7: Wajar tanpa pengecualian | BF7: =B7 -> 44561 | BG7: Audited - Unqualified | BI7: KAP
B8: =+G13 -> 44926 | E8: Audited | G8: KAP | K8: Unqualified | O8: Home Statement | P8: B | Q8: Wajar dengan pengecualian | BF8: =B8 -> 44926 | BG8: Audited - Unqualified | BI8: KAP
B9: =+I13 -> 45291 | E9: Audited | G9: KAP | K9: Unqualified | P9: C | Q9: Tidak wajar | BF9: =B9 -> 45291 | BG9: Audited - Unqualified | BI9: KAP
B10: =+K13 -> 45473 | E10: Home Statement | G10: N / A | K10: =IF(NOT(ISERROR(FIND("-",BG10))),RIGHT(BG10,LEN(BG10)-FIND("-",BG10)),"") | P10: D | Q10: Tidak memberikan pendapat | BF10: =B10 -> 45473 | BG10: Home Statement | BI10: N/A
B11: BALANCE SHEET STATEMENT | P11: Non Rekanan | BG11: Neraca
B12: Financial Statement Unit | E12: HISTORICAL | BG12: Satuan laporan keuangan | BJ12: HISTORIS
B13: =BD13&" "&BE13 -> IDR Million | E13: 44561 | F13: =+MONTH(E13)*30 -> 360 | G13: 44926 | H13: =+MONTH(G13)*30 -> 360 | I13: 45291 | J13: =+MONTH(I13)*30 -> 360 | K13: 45473 | L13: =+MONTH(K13)*30 -> 180 | BD13: IDR | BE13: Million | BG13: Rp. Juta | BJ13: =IF(ISNUMBER(VALUE(LEFT(BJ14,1))),DATE(RIGHT(TEXT(BJ14,"a"),4),LEFT(RIGHT(TEXT(BJ14,"a"),7),2),IF(LEN(TEXT(BJ14,"a"))=10,LEFT(TEXT(BJ14,"a"),2),LEFT(TEXT(BJ14,"a"),1))), ) -> #VALUE! | BK13: =+MONTH(BJ13)*30 -> #VALUE! | BL13: =IF(ISNUMBER(VALUE(LEFT(BL14,1))),DATE(RIGHT(TEXT(BL14,"a"),4),LEFT(RIGHT(TEXT(BL14,"a"),7),2),IF(LEN(TEXT(BL14,"a"))=10,LEFT(TEXT(BL14,"a"),2),LEFT(TEXT(BL14,"a"),1))), ) -> #VALUE! | BM13: =+MONTH(BL13)*30 -> #VALUE! | BN13: =IF(ISNUMBER(VALUE(LEFT(BN14,1))),DATE(RIGHT(TEXT(BN14,"a"),4),LEFT(RIGHT(TEXT(BN14,"a"),7),2),IF(LEN(TEXT(BN14,"a"))=10,LEFT(TEXT(BN14,"a"),2),LEFT(TEXT(BN14,"a"),1))), ) -> #VALUE! | BO13: =+MONTH(BN13)*30 -> #VALUE! | BP13: =IF(ISNUMBER(VALUE(LEFT(BP14,1))),DATE(RIGHT(TEXT(BP14,"a"),4),LEFT(RIGHT(TEXT(BP14,"a"),7),2),IF(LEN(TEXT(BP14,"a"))=10,LEFT(TEXT(BP14,"a"),2),LEFT(TEXT(BP14,"a"),1))), ) -> #VALUE! | BQ13: =+MONTH(BP13)*30 -> #VALUE!
E14: 42004 | G14: 42369 | I14: 42735 | K14: 45473 | BJ14: 42004 | BL14: 42369 | BN14: 42735 | BP14: 43100
E15: Amount | F15: % | G15: Amount | H15: % | I15: Amount | J15: % | K15: Amount | L15: % | BJ15: JUMLAH | BK15: % | BL15: JUMLAH | BM15: % | BN15: JUMLAH | BO15: % | BP15: JUMLAH | BQ15: %
B16: 1 | C16: Cash and Cash Equivalents | E16: 100 | F16: =IF(E$73=0,0,E16/E$73*100) -> 0.081168831 | G16: 101 | H16: =IF(G$73=0,0,G16/G$73*100) -> 0.081904067 | I16: 102 | J16: =IF(I$73=0,0,I16/I$73*100) -> 0.082637932 | K16: 103 | L16: =IF(K$73=0,0,K16/K$73*100) -> 0.083370432 | U16: 0 | W16: 0 | Y16: 0 | AA16: 0 | BG16: 1 | BH16: Kas dan Setara | BJ16: 1195.4833 | BK16: =IF(BJ$299=0,0,BJ16/BJ$299*100) -> 84.09149 | BL16: 506.07126 | BM16: =IF(BL$299=0,0,BL16/BL$299*100) -> 2.2592023 | BN16: 2370.9002 | BO16: =IF(BN$299=0,0,BN16/BN$299*100) -> 8.1735057 | BP16: 149989.07 | BQ16: =IF(BP$299=0,0,BP16/BP$299*100) -> 38.905636
B17: =B16+1 -> 2 | C17: Restricted Cash | E17: 200 | F17: =IF(E$73=0,0,E17/E$73*100) -> 0.16233766 | G17: 201 | H17: =IF(G$73=0,0,G17/G$73*100) -> 0.1629972 | I17: 202 | J17: =IF(I$73=0,0,I17/I$73*100) -> 0.16365551 | K17: 203 | L17: =IF(K$73=0,0,K17/K$73*100) -> 0.1643126
B18: =+B17+1 -> 3 | C18: Short Term Investments | E18: 300 | F18: =IF(E$73=0,0,E18/E$73*100) -> 0.24350649 | G18: 301 | H18: =IF(G$73=0,0,G18/G$73*100) -> 0.24409034 | I18: 302 | J18: =IF(I$73=0,0,I18/I$73*100) -> 0.24467309 | K18: 303 | L18: =IF(K$73=0,0,K18/K$73*100) -> 0.24525477 | BG18: 2 | BH18: Deposit Likuid Jangka Pendek | BJ18: 0 | BK18: =IF(BJ$299=0,0,BJ18/BJ$299*100) -> 0 | BL18: 0 | BM18: =IF(BL$299=0,0,BL18/BL$299*100) -> 0 | BN18: 0 | BO18: =IF(BN$299=0,0,BN18/BN$299*100) -> 0 | BP18: 0 | BQ18: =IF(BP$299=0,0,BP18/BP$299*100) -> 0
B19: =+B18+1 -> 4 | C19: Account Receivables | E19: 400 | F19: =IF(E$73=0,0,E19/E$73*100) -> 0.32467532 | G19: 401 | H19: =IF(G$73=0,0,G19/G$73*100) -> 0.32518347 | I19: 402 | J19: =IF(I$73=0,0,I19/I$73*100) -> 0.32569067 | K19: 403 | L19: =IF(K$73=0,0,K19/K$73*100) -> 0.32619693 | BU19: 3 | BV19: Surat Berharga | BX19: 0 | BY19: =IF(BJ$299=0,0,BX19/BJ$299*100) -> 0 | BZ19: 0 | CA19: =IF(BL$299=0,0,BZ19/BL$299*100) -> 0 | CB19: 0 | CC19: =IF(BN$299=0,0,CB19/BN$299*100) -> 0 | CD19: 0 | CE19: =IF(BP$299=0,0,CD19/BP$299*100) -> 0
B20: =+B19+1 -> 5 | C20: Inventories | E20: 500 | F20: =IF(E$73=0,0,E20/E$73*100) -> 0.40584416 | G20: 501 | H20: =IF(G$73=0,0,G20/G$73*100) -> 0.40627661 | I20: 502 | J20: =IF(I$73=0,0,I20/I$73*100) -> 0.40670826 | K20: 503 | L20: =IF(K$73=0,0,K20/K$73*100) -> 0.4071391 | BG20: 4 | BJ20: 0 | BK20: =IF(BJ$299=0,0,BJ20/BJ$299*100) -> 0 | BL20: 0 | BM20: =IF(BL$299=0,0,BL20/BL$299*100) -> 0 | BN20: 0 | BO20: =IF(BN$299=0,0,BN20/BN$299*100) -> 0 | BP20: 0 | BQ20: =IF(BP$299=0,0,BP20/BP$299*100) -> 0
B21: =+B20+1 -> 6 | C21: Prepaid Taxes | E21: 600 | F21: =IF(E$73=0,0,E21/E$73*100) -> 0.48701299 | G21: 601 | H21: =IF(G$73=0,0,G21/G$73*100) -> 0.48736974 | I21: 602 | J21: =IF(I$73=0,0,I21/I$73*100) -> 0.48772584 | K21: 603 | L21: =IF(K$73=0,0,K21/K$73*100) -> 0.48808127 | BG21: 5 | BJ21: 0 | BK21: =IF(BJ$299=0,0,BJ21/BJ$299*100) -> 0 | BL21: 0 | BM21: =IF(BL$299=0,0,BL21/BL$299*100) -> 0 | BN21: 0 | BO21: =IF(BN$299=0,0,BN21/BN$299*100) -> 0 | BP21: 0 | BQ21: =IF(BP$299=0,0,BP21/BP$299*100) -> 0
B22: =+B21+1 -> 7 | C22: Prepaid Expenses | E22: 700 | F22: =IF(E$73=0,0,E22/E$73*100) -> 0.56818182 | G22: 701 | H22: =IF(G$73=0,0,G22/G$73*100) -> 0.56846288 | I22: 702 | J22: =IF(I$73=0,0,I22/I$73*100) -> 0.56874342 | K22: 703 | L22: =IF(K$73=0,0,K22/K$73*100) -> 0.56902343 | BG22: 6 | BJ22: 0 | BK22: =IF(BJ$299=0,0,BJ22/BJ$299*100) -> 0 | BL22: 0 | BM22: =IF(BL$299=0,0,BL22/BL$299*100) -> 0 | BN22: 0 | BO22: =IF(BN$299=0,0,BN22/BN$299*100) -> 0 | BP22: 0 | BQ22: =IF(BP$299=0,0,BP22/BP$299*100) -> 0
B23: =+B22+1 -> 8 | C23: Advance Payments | E23: 800 | F23: =IF(E$73=0,0,E23/E$73*100) -> 0.64935065 | G23: 801 | H23: =IF(G$73=0,0,G23/G$73*100) -> 0.64955602 | I23: 802 | J23: =IF(I$73=0,0,I23/I$73*100) -> 0.649761 | K23: 803 | L23: =IF(K$73=0,0,K23/K$73*100) -> 0.6499656 | BG23: 7 | BJ23: 0 | BK23: =IF(BJ$299=0,0,BJ23/BJ$299*100) -> 0 | BL23: 0 | BM23: =IF(BL$299=0,0,BL23/BL$299*100) -> 0 | BN23: 0 | BO23: =IF(BN$299=0,0,BN23/BN$299*100) -> 0 | BP23: 0 | BQ23: =IF(BP$299=0,0,BP23/BP$299*100) -> 0
B24: =+B23+1 -> 9 | C24: Other Current Assets | E24: 900 | F24: =IF(E$73=0,0,E24/E$73*100) -> 0.73051948 | G24: 901 | H24: =IF(G$73=0,0,G24/G$73*100) -> 0.73064915 | I24: 902 | J24: =IF(I$73=0,0,I24/I$73*100) -> 0.73077858 | K24: 903 | L24: =IF(K$73=0,0,K24/K$73*100) -> 0.73090777 | BG24: 8 | BJ24: 0 | BK24: =IF(BJ$299=0,0,BJ24/BJ$299*100) -> 0 | BL24: 0 | BM24: =IF(BL$299=0,0,BL24/BL$299*100) -> 0 | BN24: 0 | BO24: =IF(BN$299=0,0,BN24/BN$299*100) -> 0 | BP24: 0 | BQ24: =IF(BP$299=0,0,BP24/BP$299*100) -> 0
B25: =+B24+1 -> 10 | C25: Total Current Assets | E25: =SUM(E16:E24) -> 4500 | F25: =IF(E$73=0,0,E25/E$73*100) -> 3.6525974 | G25: =SUM(G16:G24) -> 4509 | H25: =IF(G$73=0,0,G25/G$73*100) -> 3.6564895 | I25: =SUM(I16:I24) -> 4518 | J25: =IF(I$73=0,0,I25/I$73*100) -> 3.6603743 | K25: =SUM(K16:K24) -> 4527 | L25: =IF(K$73=0,0,K25/K$73*100) -> 3.6642519 | BG25: 9 | BJ25: 0 | BK25: =IF(BJ$299=0,0,BJ25/BJ$299*100) -> 0 | BL25: 0 | BM25: =IF(BL$299=0,0,BL25/BL$299*100) -> 0 | BN25: 0 | BO25: =IF(BN$299=0,0,BN25/BN$299*100) -> 0 | BP25: 0 | BQ25: =IF(BP$299=0,0,BP25/BP$299*100) -> 0
B26: =+B25+1 -> 11 | C26: Fixed Assets | E26: 110000 | F26: =IF(E$73=0,0,E26/E$73*100) -> 89.285714 | G26: 110100 | H26: =IF(G$73=0,0,G26/G$73*100) -> 89.283542 | I26: 110200 | J26: =IF(I$73=0,0,I26/I$73*100) -> 89.281374 | K26: 110300 | L26: =IF(K$73=0,0,K26/K$73*100) -> 89.27921 | BG26: 10 | BJ26: 0 | BK26: =IF(BJ$299=0,0,BJ26/BJ$299*100) -> 0 | BL26: 0 | BM26: =IF(BL$299=0,0,BL26/BL$299*100) -> 0 | BN26: 0 | BO26: =IF(BN$299=0,0,BN26/BN$299*100) -> 0 | BP26: 0 | BQ26: =IF(BP$299=0,0,BP26/BP$299*100) -> 0
B27: =+B26+1 -> 12 | C27: Investment in Associates | E27: 1200 | F27: =IF(E$73=0,0,E27/E$73*100) -> 0.97402597 | G27: 1201 | H27: =IF(G$73=0,0,G27/G$73*100) -> 0.97392856 | I27: 1202 | J27: =IF(I$73=0,0,I27/I$73*100) -> 0.97383132 | K27: 1203 | L27: =IF(K$73=0,0,K27/K$73*100) -> 0.97373427 | BG27: 11 | BJ27: 0 | BK27: =IF(BJ$299=0,0,BJ27/BJ$299*100) -> 0 | BL27: 0 | BM27: =IF(BL$299=0,0,BL27/BL$299*100) -> 0 | BN27: 0 | BO27: =IF(BN$299=0,0,BN27/BN$299*100) -> 0 | BP27: 0 | BQ27: =IF(BP$299=0,0,BP27/BP$299*100) -> 0
B28: =B27+1 -> 13 | C28: Investment in Joint Venture | E28: 1300 | F28: =IF(E$73=0,0,E28/E$73*100) -> 1.0551948 | G28: 1301 | H28: =IF(G$73=0,0,G28/G$73*100) -> 1.0550217 | I28: 1302 | J28: =IF(I$73=0,0,I28/I$73*100) -> 1.0548489 | K28: 1303 | L28: =IF(K$73=0,0,K28/K$73*100) -> 1.0546764
B29: =B28+1 -> 14 | C29: Intangible Assets | E29: 1400 | F29: =IF(E$73=0,0,E29/E$73*100) -> 1.1363636 | G29: 1401 | H29: =IF(G$73=0,0,G29/G$73*100) -> 1.1361148 | I29: 1402 | J29: =IF(I$73=0,0,I29/I$73*100) -> 1.1358665 | K29: 1403 | L29: =IF(K$73=0,0,K29/K$73*100) -> 1.1356186
B30: 15 | C30: Deferred Taxes | E30: 1500 | F30: =IF(E$73=0,0,E30/E$73*100) -> 1.2175325 | G30: 1501 | H30: =IF(G$73=0,0,G30/G$73*100) -> 1.217208 | I30: 1502 | J30: =IF(I$73=0,0,I30/I$73*100) -> 1.2168841 | K30: 1503 | L30: =IF(K$73=0,0,K30/K$73*100) -> 1.2165608 | BG30: 12 | BJ30: 0 | BK30: =IF(BJ$299=0,0,BJ30/BJ$299*100) -> 0 | BL30: 0 | BM30: =IF(BL$299=0,0,BL30/BL$299*100) -> 0 | BN30: 0 | BO30: =IF(BN$299=0,0,BN30/BN$299*100) -> 0 | BP30: 0 | BQ30: =IF(BP$299=0,0,BP30/BP$299*100) -> 0
B31: 16 | C31: Other Non-Current Assets | E31: 1600 | F31: =IF(E$73=0,0,E31/E$73*100) -> 1.2987013 | G31: 1601 | H31: =IF(G$73=0,0,G31/G$73*100) -> 1.2983011 | I31: 1602 | J31: =IF(I$73=0,0,I31/I$73*100) -> 1.2979016 | K31: 1603 | L31: =IF(K$73=0,0,K31/K$73*100) -> 1.2975029 | BG31: 13 | BJ31: 0 | BK31: =IF(BJ$299=0,0,BJ31/BJ$299*100) -> 0 | BL31: 0 | BM31: =IF(BL$299=0,0,BL31/BL$299*100) -> 0 | BN31: 0 | BO31: =IF(BN$299=0,0,BN31/BN$299*100) -> 0 | BP31: 0 | BQ31: =IF(BP$299=0,0,BP31/BP$299*100) -> 0
B32: 17 | C32: Investments | E32: 1700 | F32: =IF(E$73=0,0,E32/E$73*100) -> 1.3798701 | G32: 1701 | H32: =IF(G$73=0,0,G32/G$73*100) -> 1.3793942 | I32: 1702 | J32: =IF(I$73=0,0,I32/I$73*100) -> 1.3789192 | K32: 1703 | L32: =IF(K$73=0,0,K32/K$73*100) -> 1.3784451 | BG32: 14 | BJ32: 0 | BK32: =IF(BJ$299=0,0,BJ32/BJ$299*100) -> 0 | BL32: 0 | BM32: =IF(BL$299=0,0,BL32/BL$299*100) -> 0 | BN32: 0 | BO32: =IF(BN$299=0,0,BN32/BN$299*100) -> 0 | BP32: 0 | BQ32: =IF(BP$299=0,0,BP32/BP$299*100) -> 0
B33: =+B32+1 -> 18 | C33: Total Non-Current Assets | E33: =SUM(E26:E32) -> 118700 | F33: =IF(E$73=0,0,E33/E$73*100) -> 96.347403 | G33: =SUM(G26:G32) -> 118806 | H33: =IF(G$73=0,0,G33/G$73*100) -> 96.343511 | I33: =SUM(I26:I32) -> 118912 | J33: =IF(I$73=0,0,I33/I$73*100) -> 96.339626 | K33: =SUM(K26:K32) -> 119018 | L33: =IF(K$73=0,0,K33/K$73*100) -> 96.335748 | BG33: 15 | BJ33: 0 | BK33: =IF(BJ$299=0,0,BJ33/BJ$299*100) -> 0 | BL33: 0 | BM33: =IF(BL$299=0,0,BL33/BL$299*100) -> 0 | BN33: 0 | BO33: =IF(BN$299=0,0,BN33/BN$299*100) -> 0 | BP33: 0 | BQ33: =IF(BP$299=0,0,BP33/BP$299*100) -> 0
B34: =+B33+1 -> 19 | C34: TOTAL ASSETS | E34: =E25+E33 -> 123200 | F34: =IF(E$73=0,0,E34/E$73*100) -> 100 | G34: =G25+G33 -> 123315 | H34: =IF(G$73=0,0,G34/G$73*100) -> 100 | I34: =I25+I33 -> 123430 | J34: =IF(I$73=0,0,I34/I$73*100) -> 100 | K34: =K25+K33 -> 123545 | L34: =IF(K$73=0,0,K34/K$73*100) -> 100 | U34: 157881.1 | W34: 303530.54 | Y34: 310346.08 | AA34: 597520.23
B35: =+B34+1 -> 20 | C35: Short-Term Bank Loan - BNI | E35: 2000 | F35: =IF(E$73=0,0,E35/E$73*100) -> 1.6233766 | G35: 2001 | H35: =IF(G$73=0,0,G35/G$73*100) -> 1.6226736 | I35: 2002 | J35: =IF(I$73=0,0,I35/I$73*100) -> 1.621972 | K35: 2003 | L35: =IF(K$73=0,0,K35/K$73*100) -> 1.6212716 | BU35: 16 | BV35: Piutang Usaha | BX35: 682.12144 | BY35: =IF(L$253=0,0,BX35/L$253*100) -> 0 | BZ35: 5054.491 | CA35: =IF(N$299=0,0,BZ35/N$299*100) -> 0 | CB35: 6414.4736 | CC35: =IF(P$299=0,0,CB35/P$299*100) -> 0 | CD35: 136969.56 | CE35: =IF(R$299=0,0,CD35/R$299*100) -> 0
B36: =+B35+1 -> 21 | C36: Short-Term Bank Loan - Other Banks | E36: 2100 | F36: =IF(E$73=0,0,E36/E$73*100) -> 1.7045455 | G36: 2101 | H36: =IF(G$73=0,0,G36/G$73*100) -> 1.7037668 | I36: 2102 | J36: =IF(I$73=0,0,I36/I$73*100) -> 1.7029895 | K36: 2103 | L36: =IF(K$73=0,0,K36/K$73*100) -> 1.7022138 | BU36: 17 | BV36: Piutang Usaha - Pihak Berelasi | BX36: 0 | BY36: =IF(BJ$299=0,0,BX36/BJ$299*100) -> 0 | BZ36: 48 | CA36: =IF(BL$299=0,0,BZ36/BL$299*100) -> 0.21428151 | CB36: 5557.0367 | CC36: =IF(BN$299=0,0,CB36/BN$299*100) -> 19.15748 | CD36: 329.51233 | CE36: =IF(BP$299=0,0,CD36/BP$299*100) -> 0.085472139
B37: =+B36+1 -> 22 | C37: LC / TR - BNI | E37: 2200 | F37: =IF(E$73=0,0,E37/E$73*100) -> 1.7857143 | G37: 2201 | H37: =IF(G$73=0,0,G37/G$73*100) -> 1.7848599 | I37: 2202 | J37: =IF(I$73=0,0,I37/I$73*100) -> 1.7840071 | K37: 2203 | L37: =IF(K$73=0,0,K37/K$73*100) -> 1.7831559 | BU37: 18 | BV37: Piutang Usaha - Pihak Ketiga | BX37: 0 | BY37: =IF(BJ$299=0,0,BX37/BJ$299*100) -> 0 | BZ37: 0 | CA37: =IF(BL$299=0,0,BZ37/BL$299*100) -> 0 | CB37: 0 | CC37: =IF(BN$299=0,0,CB37/BN$299*100) -> 0 | CD37: 0 | CE37: =IF(BP$299=0,0,CD37/BP$299*100) -> 0
B38: =+B37+1 -> 23 | C38: LC / TR - Other Banks | E38: 2300 | F38: =IF(E$73=0,0,E38/E$73*100) -> 1.8668831 | G38: 2301 | H38: =IF(G$73=0,0,G38/G$73*100) -> 1.865953 | I38: 2302 | J38: =IF(I$73=0,0,I38/I$73*100) -> 1.8650247 | K38: 2303 | L38: =IF(K$73=0,0,K38/K$73*100) -> 1.8640981 | BU38: 19 | BX38: 0 | BY38: =IF(L$253=0,0,BX38/L$253*100) -> 0 | BZ38: 0 | CA38: =IF(N$299=0,0,BZ38/N$299*100) -> 0 | CB38: 0 | CC38: =IF(P$299=0,0,CB38/P$299*100) -> 0 | CD38: 0 | CE38: =IF(R$299=0,0,CD38/R$299*100) -> 0
B39: =+B38+1 -> 24 | C39: Account Payables | E39: 2400 | F39: =IF(E$73=0,0,E39/E$73*100) -> 1.9480519 | G39: 2401 | H39: =IF(G$73=0,0,G39/G$73*100) -> 1.9470462 | I39: 2402 | J39: =IF(I$73=0,0,I39/I$73*100) -> 1.9460423 | K39: 2403 | L39: =IF(K$73=0,0,K39/K$73*100) -> 1.9450403 | BU39: 20 | BX39: 0 | BY39: =IF(BJ$299=0,0,BX39/BJ$299*100) -> 0 | BZ39: 0 | CA39: =IF(BL$299=0,0,BZ39/BL$299*100) -> 0 | CB39: 0 | CC39: =IF(BN$299=0,0,CB39/BN$299*100) -> 0 | CD39: 0 | CE39: =IF(BP$299=0,0,CD39/BP$299*100) -> 0
B40: =+B39+1 -> 25 | C40: Tax Payables | E40: 2500 | F40: =IF(E$73=0,0,E40/E$73*100) -> 2.0292208 | G40: 2501 | H40: =IF(G$73=0,0,G40/G$73*100) -> 2.0281393 | I40: 2502 | J40: =IF(I$73=0,0,I40/I$73*100) -> 2.0270599 | K40: 2503 | L40: =IF(K$73=0,0,K40/K$73*100) -> 2.0259824 | BU40: 21 | BX40: 0 | BY40: =IF(BJ$299=0,0,BX40/BJ$299*100) -> 0 | BZ40: 0 | CA40: =IF(BL$299=0,0,BZ40/BL$299*100) -> 0 | CB40: 0 | CC40: =IF(BN$299=0,0,CB40/BN$299*100) -> 0 | CD40: 0 | CE40: =IF(BP$299=0,0,CD40/BP$299*100) -> 0
B41: =+B40+1 -> 26 | C41: Shareholder & Related Parties Loans- Short Term | E41: 2600 | F41: =IF(E$73=0,0,E41/E$73*100) -> 2.1103896 | G41: 2601 | H41: =IF(G$73=0,0,G41/G$73*100) -> 2.1092325 | I41: 2602 | J41: =IF(I$73=0,0,I41/I$73*100) -> 2.1080775 | K41: 2603 | L41: =IF(K$73=0,0,K41/K$73*100) -> 2.1069246 | BU41: 22 | BX41: 0 | BY41: =IF(BJ$299=0,0,BX41/BJ$299*100) -> 0 | BZ41: 0 | CA41: =IF(BL$299=0,0,BZ41/BL$299*100) -> 0 | CB41: 0 | CC41: =IF(BN$299=0,0,CB41/BN$299*100) -> 0 | CD41: 0 | CE41: =IF(BP$299=0,0,CD41/BP$299*100) -> 0
B42: =+B41+1 -> 27 | C42: Accrued Expenses | E42: 2700 | F42: =IF(E$73=0,0,E42/E$73*100) -> 2.1915584 | G42: 2701 | H42: =IF(G$73=0,0,G42/G$73*100) -> 2.1903256 | I42: 2702 | J42: =IF(I$73=0,0,I42/I$73*100) -> 2.189095 | K42: 2703 | L42: =IF(K$73=0,0,K42/K$73*100) -> 2.1878668 | BU42: 23 | BX42: 0 | BY42: =IF(BJ$299=0,0,BX42/BJ$299*100) -> 0 | BZ42: 0 | CA42: =IF(BL$299=0,0,BZ42/BL$299*100) -> 0 | CB42: 0 | CC42: =IF(BN$299=0,0,CB42/BN$299*100) -> 0 | CD42: 0 | CE42: =IF(BP$299=0,0,CD42/BP$299*100) -> 0
...

Sheet Assumption
C3: ASSUMPTIONS OF FINANCIAL PROJECTIONS
R5: ---
R6: =DATE(YEAR(Historical!K13),MONTH(Historical!K13)+1,VLOOKUP(MONTH(Historical!K13)+1,$T$6:$U$20,2)) -> 45504 | T6: 1 | U6: 31
D7: 1 | E7: Assumptions of Sales | R7: =DATE(YEAR(R6),MONTH(R6)+1,VLOOKUP(MONTH(R6)+1,$T$6:$U$19,2)) -> 45535 | T7: 2 | U7: 28
F8: Realization: | G8: =+Historical!B13 -> IDR Million | H8: Growth (%) | R8: =DATE(YEAR(R7),MONTH(R7)+1,VLOOKUP(MONTH(R7)+1,$T$6:$U$19,2)) -> 45565 | T8: 3 | U8: 31
F9: =+Historical!E13 -> 44561 | G9: =+Historical!E105 -> 100000 | H9: N/A | R9: =DATE(YEAR(R8),MONTH(R8)+1,VLOOKUP(MONTH(R8)+1,$T$6:$U$19,2)) -> 45596 | T9: 4 | U9: 30
F10: =+Historical!G13 -> 44926 | G10: =+Historical!G105 -> 110000 | H10: =Historical!G129 -> 10 | R10: =DATE(YEAR(R9),MONTH(R9)+1,VLOOKUP(MONTH(R9)+1,$T$6:$U$19,2)) -> 45626 | T10: 5 | U10: 31
F11: =+Historical!I13 -> 45291 | G11: =+Historical!I105 -> 120000 | H11: =Historical!I129 -> 9.0909091 | R11: =DATE(YEAR(R10),MONTH(R10)+1,VLOOKUP(MONTH(R10)+1,$T$6:$U$19,2)) -> 45656 | T11: 6 | U11: 30
F12: =+Historical!K13 -> 45473 | G12: =Historical!K105 -> 130000 | H12: =Historical!K129 -> 116.66667 | R12: =DATE(YEAR(R11),MONTH(R11)+1,VLOOKUP(MONTH(R11)+1,$T$6:$U$19,2)) -> 45687 | T12: 7 | U12: 31
R13: =DATE(YEAR(R12),MONTH(R12)+1,VLOOKUP(MONTH(R12)+1,$T$6:$U$19,2)) -> 45716 | T13: 8 | U13: 31
F14: Assumptions of Projections Sales Growth: | R14: =DATE(YEAR(R13),MONTH(R13)+1,VLOOKUP(MONTH(R13)+1,$T$6:$U$19,2)) -> 45747 | T14: 9 | U14: 30
F15: =+IF(MONTH(F12)=12,DATE(YEAR(F12)+1,12,31),DATE(YEAR(F11)+1,12,31)) -> 45657 | G15: =IF(K15=F12,G12*(1+I15),G11*(1+I15)) -> 132000 | H15: Growth (%) | I15: =+(SUM(J23:J26)-G12)/G12 -> 0.1 | J15: from | K15: =+IF(MONTH(F12)=12,F12,F11) -> 45291 | R15: =DATE(YEAR(R14),MONTH(R14)+1,VLOOKUP(MONTH(R14)+1,$T$6:$U$19,2)) -> 45777 | T15: 10 | U15: 31
F17: =+IF(MONTH(F12)=12,"",IF(G15<G12,"Agar input asumsi Growth lainnya, karena posisi Sales di bulan Desember harus lebih besar dari posisi terakhir !!",""))
F19: Reason of assumptions : | R19: =DATE(YEAR(R15),MONTH(R15)+1,VLOOKUP(MONTH(R15)+1,$T$6:$U$19,2)) -> 45808 | T19: 11 | U19: 30
R20: =DATE(YEAR(R19),MONTH(R19)+1,VLOOKUP(MONTH(R19)+1,$T$6:$U$19,2)) -> 45838 | T20: 12 | U20: 31
F21: Description | G21: Volume | H21: Price/Unit | J21: Sales
H22: ="("&Historical!$B$13&")" -> (IDR Million) | J22: ="("&Historical!$B$13&")" -> (IDR Million)
F23: Product A | G23: 10000 | H23: 14.3 | J23: =+G23*H23 -> 143000
F24: Product B | G24: 0 | H24: 0 | J24: =+G24*H24 -> 0
F25: Product C | G25: 0 | H25: 0 | J25: =+G25*H25 -> 0
F26: Product D | G26: 0 | H26: 0 | J26: =+G26*H26 -> 0
R27: =DATE(YEAR(R20),MONTH(R20)+1,VLOOKUP(MONTH(R20)+1,$T$6:$U$19,2)) -> 45869
F28: =DATE(YEAR(F15)+1,12,31) -> 46022 | G28: =+G15*(1+I28) -> 157300 | H28: Growth (%) | I28: =+(SUM(J33:J36)-G15)/G15 -> 0.19166667 | J28: dari | K28: =+F15 -> 45657 | R28: =DATE(YEAR(R27),MONTH(R27)+1,VLOOKUP(MONTH(R27)+1,$T$6:$U$19,2)) -> 45900
F29: Reason of assumptions : | R29: =DATE(YEAR(R28),MONTH(R28)+1,VLOOKUP(MONTH(R28)+1,$T$6:$U$19,2)) -> 45930
R30: =DATE(YEAR(R29),MONTH(R29)+1,VLOOKUP(MONTH(R29)+1,$T$6:$U$19,2)) -> 45961
F31: Description | G31: Volume | H31: Price/Unit | J31: Sales
H32: ="("&Historical!$B$13&")" -> (IDR Million) | J32: ="("&Historical!$B$13&")" -> (IDR Million)
F33: Product A | G33: 11000 | H33: 14.3 | J33: =+G33*H33 -> 157300
F34: Product B | G34: 0 | H34: 0 | J34: =+G34*H34 -> 0
F35: Product C | G35: 0 | H35: 0 | J35: =+G35*H35 -> 0
F36: Product D | G36: 0 | H36: 0 | J36: =+G36*H36 -> 0
R37: =DATE(YEAR(R30),MONTH(R30)+1,VLOOKUP(MONTH(R30)+1,$T$6:$U$19,2)) -> 45991
F38: =DATE(YEAR(F28)+1,12,31) -> 46387 | G38: =+G28*(1+I38) -> 173030 | H38: Growth (%) | I38: =+(SUM(J43:J46)-G28)/G28 -> 0.1 | J38: dari | K38: =+F28 -> 46022 | R38: =DATE(YEAR(R37),MONTH(R37)+1,VLOOKUP(MONTH(R37)+1,$T$6:$U$19,2)) -> 46021
F39: Reason of assumptions : | R39: =DATE(YEAR(R38),MONTH(R38)+1,VLOOKUP(MONTH(R38)+1,$T$6:$U$19,2)) -> 46052
R40: =DATE(YEAR(R39),MONTH(R39)+1,VLOOKUP(MONTH(R39)+1,$T$6:$U$19,2)) -> 46081
F41: Description | G41: Volume | H41: Price/Unit | J41: Sales
H42: ="("&Historical!$B$13&")" -> (IDR Million) | J42: ="("&Historical!$B$13&")" -> (IDR Million)
F43: Product A | G43: 11000 | H43: 15.73 | J43: =+G43*H43 -> 173030
F44: Product B | G44: 0 | H44: 0 | J44: =+G44*H44 -> 0
F45: Product C | G45: 0 | H45: 0 | J45: =+G45*H45 -> 0
...

Sheet CF
I1: =+I96/13600 -> 0.14727941
I3: =+IF(G19=0,1,G19) -> 4 | V3: =+I3 -> 4 | AI3: =+V3 -> 4 | AV3: =+AI3 -> 4 | BI3: =+AV3 -> 4 | BV3: =+BI3 -> 4 | CI3: =+BV3 -> 4 | CV3: =+CI3 -> 4 | DI3: =+CV3 -> 4 | DV3: =+DI3 -> 4
I4: =+IF(I10=0,0,1) -> 0 | J4: =+IF(J10=0,0,1) -> 0 | K4: =+IF(K10=0,0,1) -> 0 | L4: =+IF(L10=0,0,1) -> 0 | M4: =+IF(M10=0,0,1) -> 0 | N4: =+IF(N10=0,0,1) -> 0 | O4: =+IF(O10=0,0,1) -> 1 | P4: =+IF(P10=0,0,1) -> 1 | ... T4: =+IF(T10=0,0,1) -> 1 | V4: =+IF(V10=0,0,1) -> 1 | W4: =+IF(W10=0,0,1) -> 1 | X4: =+IF(X10=0,0,1) -> 1 | Y4: =+IF(Y10=0,0,1) -> 1 | Z4: =+IF(Z10=0,0,1) -> 1 | AA4: =+IF(AA10=0,0,1) -> 1 | AB4: =+IF(AB10=0,0,1) -> 1 | AC4: =+IF(AC10=0,0,1) -> 1 | ... AG4: =+IF(AG10=0,0,1) -> 1 | AI4: =+IF(AI10=0,0,1) -> 1 | AJ4: =+IF(AJ10=0,0,1) -> 1 | AK4: =+IF(AK10=0,0,1) -> 1 | AL4: =+IF(AL10=0,0,1) -> 1 | AM4: =+IF(AM10=0,0,1) -> 1 | AN4: =+IF(AN10=0,0,1) -> 1 | AO4: =+IF(AO10=0,0,1) -> 1 | AP4: =+IF(AP10=0,0,1) -> 1 | ... AT4: =+IF(AT10=0,0,1) -> 1 | AV4: =+IF(AV10=0,0,1) -> 1 | AW4: =+IF(AW10=0,0,1) -> 1 | AX4: =+IF(AX10=0,0,1) -> 1 | AY4: =+IF(AY10=0,0,1) -> 1 | AZ4: =+IF(AZ10=0,0,1) -> 1 | BA4: =+IF(BA10=0,0,1) -> 1 | BB4: =+IF(BB10=0,0,1) -> 1 | BC4: =+IF(BC10=0,0,1) -> 1 | ... BG4: =+IF(BG10=0,0,1) -> 1 | BI4: =+IF(BI10=0,0,1) -> 1 | BJ4: =+IF(BJ10=0,0,1) -> 1 | BK4: =+IF(BK10=0,0,1) -> 1 | BL4: =+IF(BL10=0,0,1) -> 1 | BM4: =+IF(BM10=0,0,1) -> 1 | BN4: =+IF(BN10=0,0,1) -> 1 | BO4: =+IF(BO10=0,0,1) -> 1 | BP4: =+IF(BP10=0,0,1) -> 1 | ... BT4: =+IF(BT10=0,0,1) -> 1 | BV4: =+IF(BV10=0,0,1) -> 1 | BW4: =+IF(BW10=0,0,1) -> 1 | BX4: =+IF(BX10=0,0,1) -> 1 | BY4: =+IF(BY10=0,0,1) -> 1 | BZ4: =+IF(BZ10=0,0,1) -> 1 | CA4: =+IF(CA10=0,0,1) -> 1 | CB4: =+IF(CB10=0,0,1) -> 1 | CC4: =+IF(CC10=0,0,1) -> 1 | ... CG4: =+IF(CG10=0,0,1) -> 1 | CI4: =+IF(CI10=0,0,1) -> 1 | CJ4: =+IF(CJ10=0,0,1) -> 1 | CK4: =+IF(CK10=0,0,1) -> 1 | CL4: =+IF(CL10=0,0,1) -> 1 | CM4: =+IF(CM10=0,0,1) -> 1 | CN4: =+IF(CN10=0,0,1) -> 1 | CO4: =+IF(CO10=0,0,1) -> 1 | CP4: =+IF(CP10=0,0,1) -> 1 | ... CT4: =+IF(CT10=0,0,1) -> 1 | CV4: =+IF(CV10=0,0,1) -> 1 | CW4: =+IF(CW10=0,0,1) -> 1 | CX4: =+IF(CX10=0,0,1) -> 1 | CY4: =+IF(CY10=0,0,1) -> 1 | CZ4: =+IF(CZ10=0,0,1) -> 1 | DA4: =+IF(DA10=0,0,1) -> 1 | DB4: =+IF(DB10=0,0,1) -> 1 | DC4: =+IF(DC10=0,0,1) -> 1 | ... DG4: =+IF(DG10=0,0,1) -> 1 | DI4: =+IF(DI10=0,0,1) -> 1 | DJ4: =+IF(DJ10=0,0,1) -> 1 | DK4: =+IF(DK10=0,0,1) -> 1 | DL4: =+IF(DL10=0,0,1) -> 1 | DM4: =+IF(DM10=0,0,1) -> 1 | DN4: =+IF(DN10=0,0,1) -> 1 | DO4: =+IF(DO10=0,0,1) -> 1 | DP4: =+IF(DP10=0,0,1) -> 1 | ... DT4: =+IF(DT10=0,0,1) -> 1 | DV4: =+IF(DV10=0,0,1) -> 1 | DW4: =+IF(DW10=0,0,1) -> 1 | DX4: =+IF(DX10=0,0,1) -> 1 | DY4: =+IF(DY10=0,0,1) -> 1 | DZ4: =+IF(DZ10=0,0,1) -> 1 | EA4: =+IF(EA10=0,0,1) -> 1 | EB4: =+IF(EB10=0,0,1) -> 1 | EC4: =+IF(EC10=0,0,1) -> 1 | ... EG4: =+IF(EG10=0,0,1) -> 1
I5: =+I4 -> 0 | J5: =+SUM($I$4:J4) -> 0 | K5: =+SUM($I$4:K4) -> 0 | L5: =+SUM($I$4:L4) -> 0 | M5: =+SUM($I$4:M4) -> 0 | N5: =+SUM($I$4:N4) -> 0 | O5: =+SUM($I$4:O4) -> 1 | P5: =+SUM($I$4:P4) -> 2 | Q5: =+SUM($I$4:Q4) -> 3 | ... T5: =+SUM($I$4:T4) -> 6 | V5: =+V4 -> 1 | W5: =+V5+1 -> 2 | X5: =+W5+1 -> 3 | Y5: =+X5+1 -> 4 | Z5: =+Y5+1 -> 5 | AA5: =+Z5+1 -> 6 | AB5: =+AA5+1 -> 7 | AC5: =+AB5+1 -> 8 | AD5: =+AC5+1 -> 9 | ... AG5: =+AF5+1 -> 12 | AI5: =+AI4 -> 1 | AJ5: =+AI5+1 -> 2 | AK5: =+AJ5+1 -> 3 | AL5: =+AK5+1 -> 4 | AM5: =+AL5+1 -> 5 | AN5: =+AM5+1 -> 6 | AO5: =+AN5+1 -> 7 | AP5: =+AO5+1 -> 8 | AQ5: =+AP5+1 -> 9 | ... AT5: =+AS5+1 -> 12 | AV5: =+AV4 -> 1 | AW5: =+AV5+1 -> 2 | AX5: =+AW5+1 -> 3 | AY5: =+AX5+1 -> 4 | AZ5: =+AY5+1 -> 5 | BA5: =+AZ5+1 -> 6 | BB5: =+BA5+1 -> 7 | BC5: =+BB5+1 -> 8 | BD5: =+BC5+1 -> 9 | ... BG5: =+BF5+1 -> 12 | BI5: =+BI4 -> 1 | BJ5: =+BI5+1 -> 2 | BK5: =+BJ5+1 -> 3 | BL5: =+BK5+1 -> 4 | BM5: =+BL5+1 -> 5 | BN5: =+BM5+1 -> 6 | BO5: =+BN5+1 -> 7 | BP5: =+BO5+1 -> 8 | BQ5: =+BP5+1 -> 9 | ... BT5: =+BS5+1 -> 12 | BV5: =+BV4 -> 1 | BW5: =+BV5+1 -> 2 | BX5: =+BW5+1 -> 3 | BY5: =+BX5+1 -> 4 | BZ5: =+BY5+1 -> 5 | CA5: =+BZ5+1 -> 6 | CB5: =+CA5+1 -> 7 | CC5: =+CB5+1 -> 8 | CD5: =+CC5+1 -> 9 | ... CG5: =+CF5+1 -> 12 | CI5: =+CI4 -> 1 | CJ5: =+CI5+1 -> 2 | CK5: =+CJ5+1 -> 3 | CL5: =+CK5+1 -> 4 | CM5: =+CL5+1 -> 5 | CN5: =+CM5+1 -> 6 | CO5: =+CN5+1 -> 7 | CP5: =+CO5+1 -> 8 | CQ5: =+CP5+1 -> 9 | ... CT5: =+CS5+1 -> 12 | CV5: =+CV4 -> 1 | CW5: =+CV5+1 -> 2 | CX5: =+CW5+1 -> 3 | CY5: =+CX5+1 -> 4 | CZ5: =+CY5+1 -> 5 | DA5: =+CZ5+1 -> 6 | DB5: =+DA5+1 -> 7 | DC5: =+DB5+1 -> 8 | DD5: =+DC5+1 -> 9 | ... DG5: =+DF5+1 -> 12 | DI5: =+DI4 -> 1 | DJ5: =+DI5+1 -> 2 | DK5: =+DJ5+1 -> 3 | DL5: =+DK5+1 -> 4 | DM5: =+DL5+1 -> 5 | DN5: =+DM5+1 -> 6 | DO5: =+DN5+1 -> 7 | DP5: =+DO5+1 -> 8 | DQ5: =+DP5+1 -> 9 | ... DT5: =+DS5+1 -> 12 | DV5: =+DV4 -> 1 | DW5: =+DV5+1 -> 2 | DX5: =+DW5+1 -> 3 | DY5: =+DX5+1 -> 4 | DZ5: =+DY5+1 -> 5 | EA5: =+DZ5+1 -> 6 | EB5: =+EA5+1 -> 7 | EC5: =+EB5+1 -> 8 | ED5: =+EC5+1 -> 9 | ... EG5: =+EF5+1 -> 12
E6: =+Historical!B3 -> Generic Niaga / Generic Group | I6: C A S H F L O W P R O J E C T I O N | V6: P R O Y E K S I C A S H F L O W | AI6: P R O Y E K S I C A S H F L O W | AV6: P R O Y E K S I C A S H F L O W | BI6: P R O Y E K S I C A S H F L O W | BV6: P R O Y E K S I C A S H F L O W | CI6: P R O Y E K S I C A S H F L O W | CV6: P R O Y E K S I C A S H F L O W | DI6: P R O Y E K S I C A S H F L O W | DV6: P R O Y E K S I C A S H F L O W
E7: =+Historical!B13 -> IDR Million
F8: Date/Month/Year : | G8: Assumption | H8: Current Post | I8: =IF(MONTH(Historical!K13)=12,DATE(YEAR(Historical!K13),MONTH(Historical!K13)+1,31),DATE(YEAR(Historical!I13),MONTH(Historical!I13)+1,31)) -> 45322 | J8: =+IF(MOD(YEAR(I8),4)=0,I8+29,I8+28) -> 45351 | K8: =DATE(YEAR(J8),MONTH(J8)+1,31) -> 45382 | L8: =DATE(YEAR(K8),MONTH(K8)+1,30) -> 45412 | M8: =DATE(YEAR(L8),MONTH(L8)+1,31) -> 45443 | N8: =DATE(YEAR(M8),MONTH(M8)+1,30) -> 45473 | O8: =DATE(YEAR(N8),MONTH(N8)+1,31) -> 45504 | P8: =DATE(YEAR(O8),MONTH(O8)+1,31) -> 45535 | Q8: =DATE(YEAR(P8),MONTH(P8)+1,30) -> 45565 | R8: =DATE(YEAR(Q8),MONTH(Q8)+1,31) -> 45596 | S8: =DATE(YEAR(R8),MONTH(R8)+1,30) -> 45626 | T8: =DATE(YEAR(S8),MONTH(S8)+1,31) -> 45657 | U8: TOTAL | V8: =DATE(YEAR(T8),MONTH(T8)+1,31) -> 45688 | W8: =+IF(MOD(YEAR(V8),4)=0,V8+29,V8+28) -> 45716 | X8: =DATE(YEAR(W8),MONTH(W8)+1,31) -> 45747 | Y8: =DATE(YEAR(X8),MONTH(X8)+1,30) -> 45777 | Z8: =DATE(YEAR(Y8),MONTH(Y8)+1,31) -> 45808 | AA8: =DATE(YEAR(Z8),MONTH(Z8)+1,30) -> 45838 | AB8: =DATE(YEAR(AA8),MONTH(AA8)+1,31) -> 45869 | AC8: =DATE(YEAR(AB8),MONTH(AB8)+1,31) -> 45900 | AD8: =DATE(YEAR(AC8),MONTH(AC8)+1,30) -> 45930 | AE8: =DATE(YEAR(AD8),MONTH(AD8)+1,31) -> 45961 | AF8: =DATE(YEAR(AE8),MONTH(AE8)+1,30) -> 45991 | AG8: =DATE(YEAR(AF8),MONTH(AF8)+1,31) -> 46022 | AH8: TOTAL | AI8: =DATE(YEAR(AG8),MONTH(AG8)+1,31) -> 46053 | AJ8: =+IF(MOD(YEAR(AI8),4)=0,AI8+29,AI8+28) -> 46081 | AK8: =DATE(YEAR(AJ8),MONTH(AJ8)+1,31) -> 46112 | AL8: =DATE(YEAR(AK8),MONTH(AK8)+1,30) -> 46142 | AM8: =DATE(YEAR(AL8),MONTH(AL8)+1,31) -> 46173 | AN8: =DATE(YEAR(AM8),MONTH(AM8)+1,30) -> 46203 | AO8: =DATE(YEAR(AN8),MONTH(AN8)+1,31) -> 46234 | AP8: =DATE(YEAR(AO8),MONTH(AO8)+1,31) -> 46265 | AQ8: =DATE(YEAR(AP8),MONTH(AP8)+1,30) -> 46295 | AR8: =DATE(YEAR(AQ8),MONTH(AQ8)+1,31) -> 46326 | AS8: =DATE(YEAR(AR8),MONTH(AR8)+1,30) -> 46356 | AT8: =DATE(YEAR(AS8),MONTH(AS8)+1,31) -> 46387 | AU8: TOTAL | AV8: =DATE(YEAR(AT8),MONTH(AT8)+1,31) -> 46418 | AW8: =+IF(MOD(YEAR(AV8),4)=0,AV8+29,AV8+28) -> 46446 | AX8: =DATE(YEAR(AW8),MONTH(AW8)+1,31) -> 46477 | AY8: =DATE(YEAR(AX8),MONTH(AX8)+1,30) -> 46507 | AZ8: =DATE(YEAR(AY8),MONTH(AY8)+1,31) -> 46538 | BA8: =DATE(YEAR(AZ8),MONTH(AZ8)+1,30) -> 46568 | BB8: =DATE(YEAR(BA8),MONTH(BA8)+1,31) -> 46599 | BC8: =DATE(YEAR(BB8),MONTH(BB8)+1,31) -> 46630 | BD8: =DATE(YEAR(BC8),MONTH(BC8)+1,30) -> 46660 | BE8: =DATE(YEAR(BD8),MONTH(BD8)+1,31) -> 46691 | BF8: =DATE(YEAR(BE8),MONTH(BE8)+1,30) -> 46721 | BG8: =DATE(YEAR(BF8),MONTH(BF8)+1,31) -> 46752 | BH8: TOTAL | BI8: =DATE(YEAR(BG8),MONTH(BG8)+1,31) -> 46783 | BJ8: =+IF(MOD(YEAR(BI8),4)=0,BI8+29,BI8+28) -> 46812 | BK8: =DATE(YEAR(BJ8),MONTH(BJ8)+1,31) -> 46843 | BL8: =DATE(YEAR(BK8),MONTH(BK8)+1,30) -> 46873 | BM8: =DATE(YEAR(BL8),MONTH(BL8)+1,31) -> 46904 | BN8: =DATE(YEAR(BM8),MONTH(BM8)+1,30) -> 46934 | BO8: =DATE(YEAR(BN8),MONTH(BN8)+1,31) -> 46965 | BP8: =DATE(YEAR(BO8),MONTH(BO8)+1,31) -> 46996 | BQ8: =DATE(YEAR(BP8),MONTH(BP8)+1,30) -> 47026 | BR8: =DATE(YEAR(BQ8),MONTH(BQ8)+1,31) -> 47057 | BS8: =DATE(YEAR(BR8),MONTH(BR8)+1,30) -> 47087 | BT8: =DATE(YEAR(BS8),MONTH(BS8)+1,31) -> 47118 | BU8: TOTAL | BV8: =DATE(YEAR(BT8),MONTH(BT8)+1,31) -> 47149 | BW8: =+IF(MOD(YEAR(BV8),4)=0,BV8+29,BV8+28) -> 47177 | BX8: =DATE(YEAR(BW8),MONTH(BW8)+1,31) -> 47208 | BY8: =DATE(YEAR(BX8),MONTH(BX8)+1,30) -> 47238 | BZ8: =DATE(YEAR(BY8),MONTH(BY8)+1,31) -> 47269 | CA8: =DATE(YEAR(BZ8),MONTH(BZ8)+1,30) -> 47299 | CB8: =DATE(YEAR(CA8),MONTH(CA8)+1,31) -> 47330 | CC8: =DATE(YEAR(CB8),MONTH(CB8)+1,31) -> 47361 | CD8: =DATE(YEAR(CC8),MONTH(CC8)+1,30) -> 47391 | CE8: =DATE(YEAR(CD8),MONTH(CD8)+1,31) -> 47422 | CF8: =DATE(YEAR(CE8),MONTH(CE8)+1,30) -> 47452 | CG8: =DATE(YEAR(CF8),MONTH(CF8)+1,31) -> 47483 | CH8: TOTAL | CI8: =DATE(YEAR(CG8),MONTH(CG8)+1,31) -> 47514 | CJ8: =+IF(MOD(YEAR(CI8),4)=0,CI8+29,CI8+28) -> 47542 | CK8: =DATE(YEAR(CJ8),MONTH(CJ8)+1,31) -> 47573 | CL8: =DATE(YEAR(CK8),MONTH(CK8)+1,30) -> 47603 | CM8: =DATE(YEAR(CL8),MONTH(CL8)+1,31) -> 47634 | CN8: =DATE(YEAR(CM8),MONTH(CM8)+1,30) -> 47664 | CO8: =DATE(YEAR(CN8),MONTH(CN8)+1,31) -> 47695 | CP8: =DATE(YEAR(CO8),MONTH(CO8)+1,31) -> 47726 | CQ8: =DATE(YEAR(CP8),MONTH(CP8)+1,30) -> 47756 | CR8: =DATE(YEAR(CQ8),MONTH(CQ8)+1,31) -> 47787 | CS8: =DATE(YEAR(CR8),MONTH(CR8)+1,30) -> 47817 | CT8: =DATE(YEAR(CS8),MONTH(CS8)+1,31) -> 47848 | CU8: TOTAL | CV8: =DATE(YEAR(CT8),MONTH(CT8)+1,31) -> 47879 | CW8: =+IF(MOD(YEAR(CV8),4)=0,CV8+29,CV8+28) -> 47907 | CX8: =DATE(YEAR(CW8),MONTH(CW8)+1,31) -> 47938 | CY8: =DATE(YEAR(CX8),MONTH(CX8)+1,30) -> 47968 | CZ8: =DATE(YEAR(CY8),MONTH(CY8)+1,31) -> 47999 | DA8: =DATE(YEAR(CZ8),MONTH(CZ8)+1,30) -> 48029 | DB8: =DATE(YEAR(DA8),MONTH(DA8)+1,31) -> 48060 | DC8: =DATE(YEAR(DB8),MONTH(DB8)+1,31) -> 48091 | DD8: =DATE(YEAR(DC8),MONTH(DC8)+1,30) -> 48121 | DE8: =DATE(YEAR(DD8),MONTH(DD8)+1,31) -> 48152 | DF8: =DATE(YEAR(DE8),MONTH(DE8)+1,30) -> 48182 | DG8: =DATE(YEAR(DF8),MONTH(DF8)+1,31) -> 48213 | DH8: TOTAL | DI8: =DATE(YEAR(DG8),MONTH(DG8)+1,31) -> 48244 | DJ8: =+IF(MOD(YEAR(DI8),4)=0,DI8+29,DI8+28) -> 48273 | DK8: =DATE(YEAR(DJ8),MONTH(DJ8)+1,31) -> 48304 | DL8: =DATE(YEAR(DK8),MONTH(DK8)+1,30) -> 48334 | DM8: =DATE(YEAR(DL8),MONTH(DL8)+1,31) -> 48365 | DN8: =DATE(YEAR(DM8),MONTH(DM8)+1,30) -> 48395 | DO8: =DATE(YEAR(DN8),MONTH(DN8)+1,31) -> 48426 | DP8: =DATE(YEAR(DO8),MONTH(DO8)+1,31) -> 48457 | DQ8: =DATE(YEAR(DP8),MONTH(DP8)+1,30) -> 48487 | DR8: =DATE(YEAR(DQ8),MONTH(DQ8)+1,31) -> 48518 | DS8: =DATE(YEAR(DR8),MONTH(DR8)+1,30) -> 48548 | DT8: =DATE(YEAR(DS8),MONTH(DS8)+1,31) -> 48579 | DU8: TOTAL | DV8: =DATE(YEAR(DT8),MONTH(DT8)+1,31) -> 48610 | DW8: =+IF(MOD(YEAR(DV8),4)=0,DV8+29,DV8+28) -> 48638 | DX8: =DATE(YEAR(DW8),MONTH(DW8)+1,31) -> 48669 | DY8: =DATE(YEAR(DX8),MONTH(DX8)+1,30) -> 48699 | DZ8: =DATE(YEAR(DY8),MONTH(DY8)+1,31) -> 48730 | EA8: =DATE(YEAR(DZ8),MONTH(DZ8)+1,30) -> 48760 | EB8: =DATE(YEAR(EA8),MONTH(EA8)+1,31) -> 48791 | EC8: =DATE(YEAR(EB8),MONTH(EB8)+1,31) -> 48822 | ED8: =DATE(YEAR(EC8),MONTH(EC8)+1,30) -> 48852 | EE8: =DATE(YEAR(ED8),MONTH(ED8)+1,31) -> 48883 | EF8: =DATE(YEAR(EE8),MONTH(EE8)+1,30) -> 48913 | EG8: =DATE(YEAR(EF8),MONTH(EF8)+1,31) -> 48944 | EH8: TOTAL
D9: 1 | F9: BEGINNING CASH BALANCE | H9: =Historical!K16 -> 103 | I9: =Historical!K16 -> 103 | J9: =+I81 -> -15910.769 | K9: =+J81 -> -15924.538 | L9: =+K81 -> -15938.306 | M9: =L81 -> -15952.075 | N9: =M81 -> -15965.844 | O9: =N81 -> -15979.612 | P9: =O81 -> 500 | Q9: =P81 -> 500 | R9: =Q81 -> 500 | S9: =R81 -> 500 | T9: =S81 -> 500 | V9: =T81 -> 500 | W9: =V81 -> 500 | X9: =W81 -> 500 | Y9: =X81 -> 500 | Z9: =Y81 -> 500 | AA9: =Z81 -> 500 | AB9: =AA81 -> 500 | AC9: =AB81 -> 500 | AD9: =AC81 -> 500 | ... AG9: =AF81 -> 500 | AI9: =AG81 -> 500 | AJ9: =AI81 -> 500 | AK9: =AJ81 -> 500 | AL9: =AK81 -> 500 | AM9: =AL81 -> 500 | AN9: =AM81 -> 500 | AO9: =AN81 -> 500 | AP9: =AO81 -> 500 | AQ9: =AP81 -> 500 | ... AT9: =AS81 -> 500 | AV9: =AT81 -> 500 | AW9: =AV81 -> 500 | AX9: =AW81 -> 500 | AY9: =AX81 -> 500 | AZ9: =AY81 -> 500 | BA9: =AZ81 -> 500 | BB9: =BA81 -> 500 | BC9: =BB81 -> 500 | BD9: =BC81 -> 500 | ... BG9: =BF81 -> 500 | BI9: =BG81 -> 500 | BJ9: =BI81 -> 500 | BK9: =BJ81 -> 500 | BL9: =BK81 -> 500 | BM9: =BL81 -> 500 | BN9: =BM81 -> 1251.0489 | BO9: =BN81 -> 3904.8579 | BP9: =BO81 -> 6503.7059 | BQ9: =BP81 -> 9494.5493 | ... BT9: =BS81 -> 13635.093 | BV9: =BT81 -> 19821.24 | BW9: =BV81 -> 49702.374 | BX9: =BW81 -> 53862.226 | BY9: =BX81 -> 55689.263 | BZ9: =BY81 -> 56521.391 | CA9: =BZ81 -> 59253.945 | CB9: =CA81 -> 60782.235 | CC9: =CB81 -> 62325.598 | CD9: =CC81 -> 64911.193 | ... CG9: =CF81 -> 65912.312 | CI9: =CG81 -> 71103.487 | CJ9: =CI81 -> 21164.558 | CK9: =CJ81 -> 29647.983 | CL9: =CK81 -> 36036.712 | CM9: =CL81 -> 35934.444 | CN9: =CM81 -> 35505.592 | CO9: =CN81 -> 36510.341 | CP9: =CO81 -> 37439.989 | CQ9: =CP81 -> 37743.369 | ... CT9: =CS81 -> 37824.268 | CV9: =CT81 -> 41368.087 | CW9: =CV81 -> 30880.049 | CX9: =CW81 -> 39363.474 | CY9: =CX81 -> 45752.204 | CZ9: =CY81 -> 45649.936 | DA9: =CZ81 -> 45221.084 | DB9: =DA81 -> 46225.833 | DC9: =DB81 -> 47155.481 | DD9: =DC81 -> 47458.861 | ... DG9: =DF81 -> 47539.76 | DI9: =DG81 -> 51083.579 | DJ9: =DI81 -> 40595.541 | DK9: =DJ81 -> 49078.966 | DL9: =DK81 -> 55467.696 | DM9: =DL81 -> 55365.427 | DN9: =DM81 -> 54936.575 | DO9: =DN81 -> 55941.324 | DP9: =DO81 -> 56870.973 | DQ9: =DP81 -> 57174.353 | ... DT9: =DS81 -> 57255.251 | DV9: =DT81 -> 60799.07 | DW9: =DV81 -> 50311.033 | DX9: =DW81 -> 58794.458 | DY9: =DX81 -> 65183.187 | DZ9: =DY81 -> 65080.919 | EA9: =DZ81 -> 64652.067 | EB9: =EA81 -> 65656.816 | EC9: =EB81 -> 66586.465 | ED9: =EC81 -> 66889.844 | ... EG9: =EF81 -> 66970.743
D10: =D9+1 -> 2 | F10: Sales | I10: =+'Sales-AR Schedule'!D22 -> 0 | J10: =+'Sales-AR Schedule'!E22 -> 0 | K10: =+'Sales-AR Schedule'!F22 -> 0 | L10: =+'Sales-AR Schedule'!G22 -> 0 | M10: =+'Sales-AR Schedule'!H22 -> 0 | N10: =+'Sales-AR Schedule'!I22 -> 0 | O10: =+'Sales-AR Schedule'!J22 -> 320 | P10: =+'Sales-AR Schedule'!K22 -> 400 | ... T10: =+'Sales-AR Schedule'!O22 -> 400 | U10: =SUM(I10:T10) -> 2000 | V10: =+'Sales-AR Schedule'!D24 -> 15730 | W10: =+'Sales-AR Schedule'!E24 -> 12584 | X10: =+'Sales-AR Schedule'!F24 -> 9438 | Y10: =+'Sales-AR Schedule'!G24 -> 12584 | Z10: =+'Sales-AR Schedule'!H24 -> 15730 | AA10: =+'Sales-AR Schedule'!I24 -> 12584 | AB10: =+'Sales-AR Schedule'!J24 -> 12584 | AC10: =+'Sales-AR Schedule'!K24 -> 15730 | ... AG10: =+'Sales-AR Schedule'!O24 -> 15730 | AH10: =SUM(V10:AG10) -> 157300 | AI10: ='Sales-AR Schedule'!D26 -> 17303 | AJ10: ='Sales-AR Schedule'!E26 -> 13842.4 | AK10: ='Sales-AR Schedule'!F26 -> 10381.8 | AL10: ='Sales-AR Schedule'!G26 -> 13842.4 | AM10: ='Sales-AR Schedule'!H26 -> 17303 | AN10: ='Sales-AR Schedule'!I26 -> 13842.4 | AO10: ='Sales-AR Schedule'!J26 -> 13842.4 | AP10: ='Sales-AR Schedule'!K26 -> 17303 | ... AT10: ='Sales-AR Schedule'!O26 -> 17303 | AU10: =SUM(AI10:AT10) -> 173030 | AV10: ='Sales-AR Schedule'!D28 -> 19033.3 | AW10: ='Sales-AR Schedule'!E28 -> 15226.64 | AX10: ='Sales-AR Schedule'!F28 -> 11419.98 | AY10: ='Sales-AR Schedule'!G28 -> 15226.64 | AZ10: ='Sales-AR Schedule'!H28 -> 19033.3 | BA10: ='Sales-AR Schedule'!I28 -> 15226.64 | BB10: ='Sales-AR Schedule'!J28 -> 15226.64 | BC10: ='Sales-AR Schedule'!K28 -> 19033.3 | ... BG10: ='Sales-AR Schedule'!O28 -> 19033.3 | BH10: =SUM(AV10:BG10) -> 190333 | BI10: =+'Sales-AR Schedule'!D30 -> 20936.63 | BJ10: =+'Sales-AR Schedule'!E30 -> 16749.304 | BK10: =+'Sales-AR Schedule'!F30 -> 12561.978 | BL10: =+'Sales-AR Schedule'!G30 -> 16749.304 | BM10: =+'Sales-AR Schedule'!H30 -> 20936.63 | BN10: =+'Sales-AR Schedule'!I30 -> 16749.304 | BO10: =+'Sales-AR Schedule'!J30 -> 16749.304 | BP10: =+'Sales-AR Schedule'!K30 -> 20936.63 | ... BT10: =+'Sales-AR Schedule'!O30 -> 20936.63 | BU10: =SUM(BI10:BT10) -> 209366.3 | BV10: =+'Sales-AR Schedule'!D32 -> 20936.63 | BW10: =+'Sales-AR Schedule'!E32 -> 16749.304 | BX10: =+'Sales-AR Schedule'!F32 -> 12561.978 | BY10: =+'Sales-AR Schedule'!G32 -> 16749.304 | BZ10: =+'Sales-AR Schedule'!H32 -> 20936.63 | CA10: =+'Sales-AR Schedule'!I32 -> 16749.304 | CB10: =+'Sales-AR Schedule'!J32 -> 16749.304 | CC10: =+'Sales-AR Schedule'!K32 -> 20936.63 | ... CG10: =+'Sales-AR Schedule'!O32 -> 20936.63 | CH10: =SUM(BV10:CG10) -> 209366.3 | CI10: =+'Sales-AR Schedule'!D34 -> 20936.63 | CJ10: =+'Sales-AR Schedule'!E34 -> 16749.304 | CK10: =+'Sales-AR Schedule'!F34 -> 12561.978 | CL10: =+'Sales-AR Schedule'!G34 -> 16749.304 | CM10: =+'Sales-AR Schedule'!H34 -> 20936.63 | CN10: =+'Sales-AR Schedule'!I34 -> 16749.304 | CO10: =+'Sales-AR Schedule'!J34 -> 16749.304 | CP10: =+'Sales-AR Schedule'!K34 -> 20936.63 | ... CT10: =+'Sales-AR Schedule'!O34 -> 20936.63 | CU10: =SUM(CI10:CT10) -> 209366.3 | CV10: =+'Sales-AR Schedule'!D36 -> 20936.63 | CW10: =+'Sales-AR Schedule'!E36 -> 16749.304 | CX10: =+'Sales-AR Schedule'!F36 -> 12561.978 | CY10: =+'Sales-AR Schedule'!G36 -> 16749.304 | CZ10: =+'Sales-AR Schedule'!H36 -> 20936.63 | DA10: =+'Sales-AR Schedule'!I36 -> 16749.304 | DB10: =+'Sales-AR Schedule'!J36 -> 16749.304 | DC10: =+'Sales-AR Schedule'!K36 -> 20936.63 | ... DG10: =+'Sales-AR Schedule'!O36 -> 20936.63 | DH10: =SUM(CV10:DG10) -> 209366.3 | DI10: =+'Sales-AR Schedule'!D38 -> 20936.63 | DJ10: =+'Sales-AR Schedule'!E38 -> 16749.304 | DK10: =+'Sales-AR Schedule'!F38 -> 12561.978 | DL10: =+'Sales-AR Schedule'!G38 -> 16749.304 | DM10: =+'Sales-AR Schedule'!H38 -> 20936.63 | DN10: =+'Sales-AR Schedule'!I38 -> 16749.304 | DO10: =+'Sales-AR Schedule'!J38 -> 16749.304 | DP10: =+'Sales-AR Schedule'!K38 -> 20936.63 | ... DT10: =+'Sales-AR Schedule'!O38 -> 20936.63 | DU10: =SUM(DI10:DT10) -> 209366.3 | DV10: =+'Sales-AR Schedule'!D40 -> 20936.63 | DW10: =+'Sales-AR Schedule'!E40 -> 16749.304 | DX10: =+'Sales-AR Schedule'!F40 -> 12561.978 | DY10: =+'Sales-AR Schedule'!G40 -> 16749.304 | DZ10: =+'Sales-AR Schedule'!H40 -> 20936.63 | EA10: =+'Sales-AR Schedule'!I40 -> 16749.304 | EB10: =+'Sales-AR Schedule'!J40 -> 16749.304 | EC10: =+'Sales-AR Schedule'!K40 -> 20936.63 | ... EG10: =+'Sales-AR Schedule'!O40 -> 20936.63 | EH10: =SUM(DV10:EG10) -> 209366.3
